Workbook

Sheet 전문가 지원서 양식
B2: 전문가 지원서
B4: 지원사업명
B5: 지원분야
B7: I. 기본정보
B8: 성명(한글, 영문) | C8: 정재민 | D8: JAEMIN JEREMY BONAVENTURA JEONG | E8: 생년월일 | F8: 1983.07.31
B9: 이메일주소 | C9: jaeminjjeong@gmail.com | E9: 전화번호(휴대폰) | F9: 010-5840-9500
B10: 주 소 | C10: 서울특별시 강남구 논현로2길 37 201호
B12: II. 학력사항 (학사 이상 기술) | E12: 경력가산 대상기간 | F12: =CONCATENATE(H18,"년") -> 2년
B13: 구분 | C13: 학교명 또는 기관명 | D13: 전공 | E13: 기간 | F13: 비고 | H13: 가산기간(Y)
B14: 학사 | C14: 서울대학교 | D14: 공과대학 | E14: 2002.03 ~ 2010.02 | F14: 학위취득
B15: 석사 | C15: CITY UNIVERSITY OF LONDON | D15: 데이터과학 | E15: 2016.09 ~ 2017.11 | F15: 학위취득 | H15: =IF(F15="학위취득",2,0) -> 2
B16: 박사 | H16: =IF(AND(F15="학위취득",F16="학위취득"), 3, IF(F16="학위취득", 5, 0)) -> 0
B17: 기타
H18: =SUM(H14:H17) -> 2
B19: III. 외국어 사항
B20: 언어 | C20: 시험명 | D20: 점수 또는 레벨 | E20: 취득일 | F20: 말하기/듣기/읽기/쓰기
B21: 영어 | C21: IELTS | D21: 7.0 | E21: 42464
B25: IV. ODA 교육 이수사항 (지원사업 또는 분야관련 경력을 최신순으로 작성)
B26: 교육과정명 | E26: 교육기관 | F26: 이수일 또는 교육기간
B27: 디지털정부 해외진출 컨설턴트 경력자 과정 | E27: 한국지능정보사회진흥원 | F27: 2025.10.20 ~ 2025.10.31
B28: 디지털 정부 국제개발협력 | E28: 한국지능정보사회진흥원 | F28: 2024.09.23 ~ 2024.09.25
B29: PDM 집중 실습 과정 | E29: 부산글로벌도시재단 | F29: 2024.07.26 ~ 2024.07.27
B30: 개발협력 M&E | E30: 부산글로벌도시재단 | F30: 2024.07.19
B32: V. 경력사항 (지원사업 또는 분야관련 경력을 최신순으로 작성) | E32: 총 근무기간 | F32: =CONCATENATE(ROUNDDOWN(I44,0),"년 ",ROUNDDOWN(J44,0),"개월") -> 10년 1개월
B33: 회사명 | C33: 근무부서/직위 | D33: 담당업무 | E33: 근무시작일 | F33: 근무종료일 | H33: 근무기간(D) | I33: 근무기간(Y) | J33: 근무기간(M)
B34: 보나벤투라 | C34: IT전문가 | D34: AI, IT 설계 정책 자문 감리 컨설팅 등 | E34: 45144 | F34: 45961 | H34: =IF(F34-E34>180,F34-E34,0) -> 817 | I34: =H34/365 -> 2.2383562
B35: 국민대학교 | C35: 소프트웨어융합대학원/강사 | D35: 데이터과학 강의 | E35: 44621 | F35: 45281 | H35: =IF(F35-E35>180,F35-E35,0) -> 660 | I35: =H35/365 -> 1.8082192
B36: 데이터엔코리아 | C36: IT컨설턴트/차장 | D36: 산업은행 ERP 구축 등 | E36: 43258 | F36: 44490 | H36: =IF(F36-E36>180,F36-E36,0) -> 1232 | I36: =H36/365 -> 3.3753425
B37: 코리아카본매니지먼트 | C37: 사업기획/대리 | D37: 사업기획 통번역 ADMIN | E37: 41654 | F37: 42018 | H37: =IF(F37-E37>180,F37-E37,0) -> 364 | I37: =H37/365 -> 0.99726027
B38: 조선일보사 | C38: 회계팀/사원 | D38: 세무, 재무회계, 전표 | E38: 40513 | F38: 40965 | H38: =IF(F38-E38>180,F38-E38,0) -> 452 | I38: =H38/365 -> 1.2383562
B39: 한국방송광고공사 | C39: 뉴미디어팀/인턴 | D39: 시스템개발 데이터분석 | E39: 40238 | F39: 40421 | H39: =IF(F39-E39>180,F39-E39,0) -> 183 | I39: =H39/365 -> 0.50136986
H40: =IF(F40-E40>180,F40-E40,0) -> 0 | I40: =H40/365 -> 0
H41: =IF(F41-E41>180,F41-E41,0) -> 0 | I41: =H41/365 -> 0
H42: =IF(F42-E42>180,F42-E42,0) -> 0 | I42: =H42/365 -> 0
H43: =IF(F43-E43>180,F43-E43,0) -> 0 | I43: =H43/365 -> 0
H44: =SUM(H34:H43) -> 3708 | I44: =H44/365 -> 10.158904 | J44: =ROUNDDOWN((I44-ROUNDDOWN(I44,0))*12,1) -> 1.9
B45: VI. 경험사항 (금전적 보수를 받지 않고 일정기간 동안 지원사업 또는 분야관련 일했던 경험을 최신순으로 작성)
B46: 회사명/기관명 | C46: 근무부서/직위 | D46: 담당업무 | E46: 근무시작일 | F46: 근무종료일 | H46: 근무기간(D) | I46: 근무기간(Y) | J46: 근무기간(M)
B47: Irish Associations of Korea | C47: Digital Officer | D47: 웹사이트 관리 이벤트 스태프 | E47: 45825
B48: PLUR | C48: Volunteer | D48: 외국인과 함께 영등포 서울역 노숙자 푸드배식 | E48: 45816
...

Sheet 전문가 지원총괄표
A1: 전문가 지원 총괄표
A2: 연번 | B2: 사업명 | C2: 이름(한글) | D2: 이름(영문) | E2: 소속 | F2: 직위 | G2: 분야 | H2: 등급 | I2: 이메일 | J2: 전화번호 | K2: 언어 1 | L2: 언어 2 | M2: 언어 3 | N2: 심사자(지역) | O2: 점수 | P2: 심사자(섹터) | Q2: 점수 | R2: 심사자(사무소) | S2: 점수 | T2: 평균
A3: 1 | B3: ='전문가 지원서 양식'!C4 | C3: ='전문가 지원서 양식'!C8 -> 정재민 | D3: ='전문가 지원서 양식'!D8 -> JAEMIN JEREMY BONAVENTURA JEONG | E3: ='전문가 지원서 양식'!B34 -> 보나벤투라 | F3: ='전문가 지원서 양식'!C34 -> IT전문가 | G3: ='전문가 지원서 양식'!C5 | I3: ='전문가 지원서 양식'!C9 -> jaeminjjeong@gmail.com | J3: ='전문가 지원서 양식'!F9 -> 010-5840-9500 | K3: =CONCATENATE('전문가 지원서 양식'!B21,'전문가 지원서 양식'!C21,'전문가 지원서 양식'!D21) -> 영어IELTS7.0 | L3: =CONCATENATE('전문가 지원서 양식'!B22,'전문가 지원서 양식'!C22,'전문가 지원서 양식'!D22) | M3: =CONCATENATE('전문가 지원서 양식'!B23,'전문가 지원서 양식'!C23,'전문가 지원서 양식'!D23) | T3: =(O3+Q3+S3)/3 -> 0

Sheet (참고) 선발 기준표
B2: 전문가 선발 심사표 (2019.12.30. 개정)
B4: 항목 | C4: 심사기준 | D4: 배점
B5: 과업 이해도 | C5: ㅇ 지원사업 이해도 | D5: 30
C6: ㅇ 과업범위 이해도 등
B7: 과업 수행능력 | C7: ㅇ 해당분야 자격요건 부합도 | D7: 20
C8: - 자격사항 또는 외국어 능력 등
C9: ㅇ 해당분야 근무경력 부합도 | D9: 30
C10: ㅇ 유사사업(ODA 포함) 참여 실적 | D10: 20
B11: 총계 | D11: 100
B13: ※ 범례
B14: - 동 지침으로 선발 예정인 모든 전문가를 대상으로 하나, 현지 전문가, 초급 전문가 또는 타 평가 체계가 필요한 경우에는 별도의 평가 항목을 설정할 수 있음
B15: ※ 종합평점에 따른 선발
B16: - 종합 평점 최고득점자 순으로 선발(80점 이상 득점자 적격 판정)하며, 최고득점자 미선발시 차순위득점자 순으로 선발 가능

Sheet (참고) 전문가등급 산정 기준 
B1: 전문가 등급 기준 <개정 2022.08.11., 2023.07.13.>
A3: 구분 | B3: 자격 요건
A4: 1급 | B4: ㅇ 국제개발협력사업 또는 해당분야 경력 20년 이상 또는 아래의 직위 요건을 충족하는 자
B5: ㅇ 3급 이상 공무원으로 3년 이상 경력자
B6: ㅇ 4년제 대학 정교수로 3년 이상 경력자
B7: ㅇ 공공기관의 임원으로 2년 이상 경력자 또는 책임연구원 상당으로 8년 이상 경력자
A8: 2급 | B8: ㅇ 국제개발협력사업 또는 해당분야 경력 15년 이상 또는 아래의 직위 요건을 충족하는 자
B9: ㅇ 4급 이상 공무원 경력자
B10: ㅇ 4년제 대학 정교수 또는 3년 이상 부교수의 경력자
B11: ㅇ 공공기관의 1급 또는 책임연구원 상당으로 5년 이상 경력자
A12: 3급 | B12: ㅇ 국제개발협력사업 또는 해당분야 경력 10년 이상 또는 아래의 직위 요건을 충족하는 자
B13: ㅇ 5급 이상 공무원 경력자
B14: ㅇ 4년제 대학 부교수 또는 2년 이상 조교수의 경력자
B15: ㅇ 공공기관의 2,3급 또는 책임연구원 상당의 경력자
A16: 4급 | B16: ㅇ 국제개발협력사업 또는 해당분야 경력 7년 이상 또는 아래의 직위 요건을 충족하는 자
B17: ㅇ 7급 이상 공무원 경력자
B18: ㅇ 4년제 대학 조교수의 경력자
B19: ㅇ 공공기관의 4급 경력자
A20: 5급 | B20: ㅇ 국제개발협력사업 또는 해당분야 경력 3년 이상을 충족하는 자
A21: 6급 | B21: ㅇ 5급에 해당되지 아니한 자
A23: ① 경력 산정에 관한 기준 - 근무 기간이 6개월 이상의 경력만 인정. 동일기간의 중복 경력 산정은 불가 - 해당분야 기준 : 다음의 8개 분야를 기준으로 산정하며, 서로 다른 분야에 대한 등급은 최대 3개까지 인정 가능 (해당경력을 분야별로 각각 반영하여 산정함)(△교육 △보건 △공공행정 △농림수산 △기술환경에너지 △성평등 △건축 △개발효과성) - 국제개발협력사업 경력 인정 기준 : △한국해외봉사단원 활동 △KOICA 해외봉사단 또는 개발협력 코디네이터 근무 경력 △UN 등 국제기구 근무 경력 △국내외 국제개발 NGO 근무 경력 △한국국제협력단 등 국제개발협력 유관 기관 근무 경력 등
A24: ② 학위 및 자격에 대한 가산 - 석사 및 박사학위 소지자는: 각 2년, 5년을 경력으로 가산하되, 둘 다 보유한 경우는 5년 가산(단, 석사 학위가 2개 이상인 경우에는 2년만 가산. 재직 중 취득한 학위 인정) - 의사, 변호사, 회계사 자격 취득자 10년 가산 의사는 의사면허증 취득자를 의미하며, 회계사는 공인회계사법 시행령 제12조 1항에 따라 실무수습을 행하고, 공인회계사법 제7조 1항에 따라 등록한 자를 말하며, 변호사는 변호사법 제7조 제1항에 따라 대한변호사협회에 등록한 자를 말한다. 해외 자격증 보유자의 경우 자격증을 취득한 국가 정부에서 공식적으로 인정하는 자격증에 한하여 동일한 기준(10년)을 적용한다. - 「국가기술자격법 시행령」 상 기술사 및 「건축사법」 상 건축사는 10년 가산, 「국가기술자격법 시행령」 상 기사는 1년 가산(단, 산업기사 자격은 가산 대상에 포함하지 않음) 기술사는 국가기술자격자 기준, 해당 전문분야의 관련 기술사자격을 가진 사람을 뜻하며, 기사는 해당 전문분야의 관련 기사자격을 가진 사람을 의미한다. 건축사는 「건축사법」에 따른 건축사를 말한다. - 학위와 자격을 둘 다 합산할 수 없음
A25: ③ 외국인 전문가 활용 시에는 국내법 기준이 아닌 해당국가 유사 법령에 따른 자격 요건 준용 가능

Sheet 참조
A1: 외국어 | B1: 자격증
A2: 영어 | B2: 의사, 변호사 또는 회계사
A3: 스페인어 | B3: 건축사 또는 기술사(산업기사X)
A4: 프랑스어 | B4: 기사(산업기사X)
A5: 아랍어 | B5: 기타
A6: 러시아어
A7: 중국어
A8: 베트남어
A9: 기타
